/home/ubuntu/airflow_venv/lib/python3.8/site-packages/airflow/jobs/scheduler_job_runner.py:203 DeprecationWarning: The '[celery] task_adoption_timeout' config option is deprecated. Please update your config to use '[scheduler] task_queued_timeout' instead.
/home/ubuntu/airflow_venv/lib/python3.8/site-packages/airflow/jobs/scheduler_job_runner.py:213 DeprecationWarning: The '[kubernetes_executor] worker_pods_pending_timeout' config option is deprecated. Please update your config to use '[scheduler] task_queued_timeout' instead.
[2024-06-29 04:35:14 +0000] [35530] [INFO] Starting gunicorn 20.1.0
[2024-06-29 04:35:14 +0000] [35530] [INFO] Listening at: http://[::]:8793 (35530)
[2024-06-29 04:35:14 +0000] [35530] [INFO] Using worker: sync
[2024-06-29 04:35:14 +0000] [35531] [INFO] Booting worker with pid: 35531
[2024-06-29 04:35:14 +0000] [35533] [INFO] Booting worker with pid: 35533
/home/ubuntu/airflow_venv/lib/python3.8/site-packages/airflow/jobs/scheduler_job_runner.py:950 DeprecationWarning: The worker_pods_pending_timeout_check_interval option in [kubernetes_executor] has been moved to the task_queued_timeout_check_interval option in [scheduler] - the old setting has been used, but please update your config.
Process ForkProcess-2:
Traceback (most recent call last):
  File "/home/ubuntu/airflow_venv/lib/python3.8/site-packages/sqlalchemy/engine/base.py", line 1900, in _execute_context
    self.dialect.do_execute(
  File "/home/ubuntu/airflow_venv/lib/python3.8/site-packages/sqlalchemy/engine/default.py", line 736, in do_execute
    cursor.execute(statement, parameters)
sqlite3.OperationalError: no such column: dag.dag_display_name

The above exception was the direct cause of the following exception:

Traceback (most recent call last):
  File "/usr/lib/python3.8/multiprocessing/process.py", line 315, in _bootstrap
    self.run()
  File "/usr/lib/python3.8/multiprocessing/process.py", line 108, in run
    self._target(*self._args, **self._kwargs)
  File "/home/ubuntu/airflow_venv/lib/python3.8/site-packages/airflow/dag_processing/manager.py", line 241, in _run_processor_manager
    processor_manager.start()
  File "/home/ubuntu/airflow_venv/lib/python3.8/site-packages/airflow/dag_processing/manager.py", line 476, in start
    return self._run_parsing_loop()
  File "/home/ubuntu/airflow_venv/lib/python3.8/site-packages/airflow/dag_processing/manager.py", line 549, in _run_parsing_loop
    self._refresh_dag_dir()
  File "/home/ubuntu/airflow_venv/lib/python3.8/site-packages/airflow/dag_processing/manager.py", line 775, in _refresh_dag_dir
    DagModel.deactivate_deleted_dags(
  File "/home/ubuntu/airflow_venv/lib/python3.8/site-packages/airflow/api_internal/internal_api_call.py", line 115, in wrapper
    return func(*args, **kwargs)
  File "/home/ubuntu/airflow_venv/lib/python3.8/site-packages/airflow/utils/session.py", line 79, in wrapper
    return func(*args, session=session, **kwargs)
  File "/home/ubuntu/airflow_venv/lib/python3.8/site-packages/airflow/models/dag.py", line 3825, in deactivate_deleted_dags
    dag_models = session.scalars(
  File "/home/ubuntu/airflow_venv/lib/python3.8/site-packages/sqlalchemy/orm/session.py", line 1773, in scalars
    return self.execute(
  File "/home/ubuntu/airflow_venv/lib/python3.8/site-packages/sqlalchemy/orm/session.py", line 1714, in execute
    result = conn._execute_20(statement, params or {}, execution_options)
  File "/home/ubuntu/airflow_venv/lib/python3.8/site-packages/sqlalchemy/engine/base.py", line 1705, in _execute_20
    return meth(self, args_10style, kwargs_10style, execution_options)
  File "/home/ubuntu/airflow_venv/lib/python3.8/site-packages/sqlalchemy/sql/elements.py", line 334, in _execute_on_connection
    return connection._execute_clauseelement(
  File "/home/ubuntu/airflow_venv/lib/python3.8/site-packages/sqlalchemy/engine/base.py", line 1572, in _execute_clauseelement
    ret = self._execute_context(
  File "/home/ubuntu/airflow_venv/lib/python3.8/site-packages/sqlalchemy/engine/base.py", line 1943, in _execute_context
    self._handle_dbapi_exception(
  File "/home/ubuntu/airflow_venv/lib/python3.8/site-packages/sqlalchemy/engine/base.py", line 2124, in _handle_dbapi_exception
    util.raise_(
  File "/home/ubuntu/airflow_venv/lib/python3.8/site-packages/sqlalchemy/util/compat.py", line 210, in raise_
    raise exception
  File "/home/ubuntu/airflow_venv/lib/python3.8/site-packages/sqlalchemy/engine/base.py", line 1900, in _execute_context
    self.dialect.do_execute(
  File "/home/ubuntu/airflow_venv/lib/python3.8/site-packages/sqlalchemy/engine/default.py", line 736, in do_execute
    cursor.execute(statement, parameters)
sqlalchemy.exc.OperationalError: (sqlite3.OperationalError) no such column: dag.dag_display_name
[SQL: SELECT dag.dag_display_name, dag.dag_id, dag.root_dag_id, dag.is_paused, dag.is_subdag, dag.is_active, dag.last_parsed_time, dag.last_pickled, dag.last_expired, dag.scheduler_lock, dag.pickle_id, dag.fileloc, dag.processor_subdir, dag.owners, dag.description, dag.default_view, dag.schedule_interval, dag.timetable_description, dag.dataset_expression, dag.max_active_tasks, dag.max_active_runs, dag.max_consecutive_failed_dag_runs, dag.has_task_concurrency_limits, dag.has_import_errors, dag.next_dagrun, dag.next_dagrun_data_interval_start, dag.next_dagrun_data_interval_end, dag.next_dagrun_create_after 
FROM dag 
WHERE dag.fileloc IS NOT NULL AND (dag.processor_subdir IS NULL OR dag.processor_subdir = ?)]
[parameters: ('/home/ubuntu/airflow/dags',)]
(Background on this error at: https://sqlalche.me/e/14/e3q8)
Traceback (most recent call last):
  File "/home/ubuntu/airflow_venv/bin/airflow", line 8, in <module>
    sys.exit(main())
  File "/home/ubuntu/airflow_venv/lib/python3.8/site-packages/airflow/__main__.py", line 58, in main
    args.func(args)
  File "/home/ubuntu/airflow_venv/lib/python3.8/site-packages/airflow/cli/cli_config.py", line 49, in command
    return func(*args, **kwargs)
  File "/home/ubuntu/airflow_venv/lib/python3.8/site-packages/airflow/utils/cli.py", line 114, in wrapper
    return f(*args, **kwargs)
  File "/home/ubuntu/airflow_venv/lib/python3.8/site-packages/airflow/utils/providers_configuration_loader.py", line 55, in wrapped_function
[2024-06-29 04:35:15 +0000] [35530] [INFO] Handling signal: term
    return func(*args, **kwargs)
  File "/home/ubuntu/airflow_venv/lib/python3.8/site-packages/airflow/cli/commands/scheduler_command.py", line 58, in scheduler
    run_command_with_daemon_option(
  File "/home/ubuntu/airflow_venv/lib/python3.8/site-packages/airflow/cli/commands/daemon_utils.py", line 80, in run_command_with_daemon_option
    callback()
  File "/home/ubuntu/airflow_venv/lib/python3.8/site-packages/airflow/cli/commands/scheduler_command.py", line 61, in <lambda>
    callback=lambda: _run_scheduler_job(args),
  File "/home/ubuntu/airflow_venv/lib/python3.8/site-packages/airflow/cli/commands/scheduler_command.py", line 49, in _run_scheduler_job
    run_job(job=job_runner.job, execute_callable=job_runner._execute)
  File "/home/ubuntu/airflow_venv/lib/python3.8/site-packages/airflow/utils/session.py", line 79, in wrapper
    return func(*args, session=session, **kwargs)
  File "/home/ubuntu/airflow_venv/lib/python3.8/site-packages/airflow/jobs/job.py", line 402, in run_job
    return execute_job(job, execute_callable=execute_callable)
  File "/home/ubuntu/airflow_venv/lib/python3.8/site-packages/airflow/jobs/job.py", line 431, in execute_job
    ret = execute_callable()
  File "/home/ubuntu/airflow_venv/lib/python3.8/site-packages/airflow/jobs/scheduler_job_runner.py", line 843, in _execute
[2024-06-29 04:35:15 +0000] [35533] [INFO] Worker exiting (pid: 35533)
[2024-06-29 04:35:15 +0000] [35531] [INFO] Worker exiting (pid: 35531)
    self._run_scheduler_loop()
  File "/home/ubuntu/airflow_venv/lib/python3.8/site-packages/airflow/jobs/scheduler_job_runner.py", line 972, in _run_scheduler_loop
    self.processor_agent.wait_until_finished()
  File "/home/ubuntu/airflow_venv/lib/python3.8/site-packages/airflow/dag_processing/manager.py", line 206, in wait_until_finished
    result = self._parent_signal_conn.recv()
  File "/usr/lib/python3.8/multiprocessing/connection.py", line 250, in recv
    buf = self._recv_bytes()
  File "/usr/lib/python3.8/multiprocessing/connection.py", line 414, in _recv_bytes
    buf = self._recv(4)
  File "/usr/lib/python3.8/multiprocessing/connection.py", line 379, in _recv
    chunk = read(handle, remaining)
ConnectionResetError: [Errno 104] Connection reset by peer
[2024-06-29 04:35:15 +0000] [35530] [INFO] Shutting down: Master
